<?xml version="1.0" ?>
<!-- =================================================================================== -->
<!-- |    This document was autogenerated by xacro from sam_bot_description.urdf       | -->
<!-- |    EDITING THIS FILE BY HAND IS NOT RECOMMENDED                                 | -->
<!-- =================================================================================== -->
<robot name="sam_bot">
  <!-- Robot Base -->
  <link name="base_link">
    <visual>
      <geometry>
        <box size="0.42 0.31 0.18"/>
      </geometry>
      <material name="Cyan">
        <color rgba="0 1.0 1.0 1.0"/>
      </material>
    </visual>
  </link>
  <!-- Robot Footprint -->
  <link name="base_footprint"/>
  <joint name="base_joint" type="fixed">
    <parent link="base_link"/>
    <child link="base_footprint"/>
    <origin rpy="0 0 0" xyz="0.0 0.0 -0.15000000000000002"/>
  </joint>
  <link name="drivewhl_l_link">
    <visual>
      <origin rpy="1.5707963267948966 0 0" xyz="0 0 0"/>
      <geometry>
        <cylinder length="0.04" radius="0.1"/>
      </geometry>
      <material name="Gray">
        <color rgba="0.5 0.5 0.5 1.0"/>
      </material>
    </visual>
  </link>
  <joint name="drivewhl_l_joint" type="continuous">
    <parent link="base_link"/>
    <child link="drivewhl_l_link"/>
    <origin rpy="0 0 0" xyz="-0.12 0.18 -0.05"/>
    <axis xyz="0 1 0"/>
  </joint>
  <link name="drivewhl_r_link">
    <visual>
      <origin rpy="1.5707963267948966 0 0" xyz="0 0 0"/>
      <geometry>
        <cylinder length="0.04" radius="0.1"/>
      </geometry>
      <material name="Gray">
        <color rgba="0.5 0.5 0.5 1.0"/>
      </material>
    </visual>
  </link>
  <joint name="drivewhl_r_joint" type="continuous">
    <parent link="base_link"/>
    <child link="drivewhl_r_link"/>
    <origin rpy="0 0 0" xyz="-0.12 -0.18 -0.05"/>
    <axis xyz="0 1 0"/>
  </joint>
  <!-- Caster Wheel -->
  <link name="front_caster">
    <visual>
      <geometry>
        <sphere radius="0.060000000000000026"/>
      </geometry>
      <material name="Cyan">
        <color rgba="0 1.0 1.0 1.0"/>
      </material>
    </visual>
  </link>
  <joint name="caster_joint" type="continuous">
    <parent link="base_link"/>
    <child link="front_caster"/>
    <axis xyz="1 1 1"/>
    <origin rpy="0 0 0" xyz="0.14 0.0 -0.09"/>
    <!-- <axis xyz="0 0 1"/> -->
  </joint>
  <collision>
    <geometry>
      <box size="0.42 0.31 0.18"/>
    </geometry>
  </collision>
  <inertial>
    <origin rpy="1.5707963267948966 0 1.5707963267948966" xyz="0 0 0"/>
    <mass value="15"/>
    <inertia ixx="0.261" ixy="0.0" ixz="0.0" iyy="0.34062499999999996" iyz="0.0" izz="0.16062500000000002"/>
  </inertial>
  <collision>
    <origin rpy="1.5707963267948966 0 0" xyz="0 0 0"/>
    <geometry>
      <cylinder length="0.04" radius="0.1"/>
    </geometry>
  </collision>
  <inertial>
    <origin rpy="1.5707963267948966 0 0" xyz="0 0 0"/>
    <mass value="0.5"/>
    <inertia ixx="0.0013166666666666667" ixy="0" ixz="0" iyy="0.0013166666666666667" iyz="0" izz="0.0025000000000000005"/>
  </inertial>
  <collision>
    <origin rpy="0 0 0" xyz="0 0 0"/>
    <geometry>
      <sphere radius="0.060000000000000026"/>
    </geometry>
  </collision>
  <inertial>
    <mass value="0.5"/>
    <inertia ixx="0.0007200000000000006" ixy="0.0" ixz="0.0" iyy="0.0007200000000000006" iyz="0.0" izz="0.0007200000000000006"/>
  </inertial>
</robot>
